2022-06-03/11:29:32		Exception occured Failed during training in module [__main__] class [ClientApp] method[train_func] Python script name [main.py] line number [204] error message [module 'json' has no attribute 'jump'] 
2022-06-03/11:33:59		Exception occured Failed during training in module [__main__] class [ClientApp] method[train_func] Python script name [main.py] line number [204] error message [module 'json' has no attribute 'jump'] 
2022-06-03/12:45:35		Exception occured Failed during training in module [cv_image_suit.utils.normal_utils.model] class [modell] method[get_model] Python script name [model.py] line number [48] error message [SavedModel file does not exist at: G:\Ineuron\DLCVNLP\cv\cv_image_suit\cv_image_suit/Checkpoint/Model_ckpt.h5/{saved_model.pbtxt|saved_model.pb}] 
2022-06-03/12:45:35		Exception occured Failed during training in module [cv_image_suit.utils.normal_utils.model] class [modell] method[get_model] Python script name [model.py] line number [180] error message [Failed during training in module [cv_image_suit.utils.normal_utils.model] class [modell] method[get_model] Python script name [model.py] line number [48] error message [SavedModel file does not exist at: G:\Ineuron\DLCVNLP\cv\cv_image_suit\cv_image_suit/Checkpoint/Model_ckpt.h5/{saved_model.pbtxt|saved_model.pb}]] 
2022-06-03/12:45:35		Exception occured Failed during training in module [__main__] class [ClientApp] method[train_func] Python script name [main.py] line number [214] error message [[Errno 2] No such file or directory: 'Logs/logs.txt']
2022-06-05/10:07:51		Exception occured Failed during training in module [cv_image_suit.Experiment_Layer.model_finder] class [modelfinder] method[find_model] Python script name [model_finder.py] line number [59] error message [[Errno 2] No such file or directory: 'Config_Layer/experiment_results.json'] 
2022-06-05/10:07:51		Exception occured Failed during training in module [__main__] class [ClientApp] method[train_func] Python script name [main.py] line number [159] error message [Failed during training in module [cv_image_suit.Experiment_Layer.model_finder] class [modelfinder] method[find_model] Python script name [model_finder.py] line number [59] error message [[Errno 2] No such file or directory: 'Config_Layer/experiment_results.json']] 
2022-06-05/10:11:12		Exception occured Failed during training in module [cv_image_suit.utils.experiment_utils.exp_model] class [modell] method[get_model] Python script name [exp_model.py] line number [33] error message [[Errno 2] No such file or directory: 'experiment_result.json'] 
2022-06-05/10:11:12		Exception occured Failed during training in module [cv_image_suit.utils.experiment_utils.exp_model] class [modell] method[get_model] Python script name [exp_model.py] line number [215] error message [Failed during training in module [cv_image_suit.utils.experiment_utils.exp_model] class [modell] method[get_model] Python script name [exp_model.py] line number [33] error message [[Errno 2] No such file or directory: 'experiment_result.json']] 
2022-06-05/10:11:12		Exception occured Failed during training in module [cv_image_suit.Experiment_Layer.model_finder] class [modelfinder] method[find_model] Python script name [model_finder.py] line number [65] error message [Failed during training in module [cv_image_suit.utils.experiment_utils.exp_model] class [modell] method[get_model] Python script name [exp_model.py] line number [215] error message [Failed during training in module [cv_image_suit.utils.experiment_utils.exp_model] class [modell] method[get_model] Python script name [exp_model.py] line number [33] error message [[Errno 2] No such file or directory: 'experiment_result.json']]] 
2022-06-05/10:11:12		Exception occured Failed during training in module [__main__] class [ClientApp] method[train_func] Python script name [main.py] line number [159] error message [Failed during training in module [cv_image_suit.Experiment_Layer.model_finder] class [modelfinder] method[find_model] Python script name [model_finder.py] line number [65] error message [Failed during training in module [cv_image_suit.utils.experiment_utils.exp_model] class [modell] method[get_model] Python script name [exp_model.py] line number [215] error message [Failed during training in module [cv_image_suit.utils.experiment_utils.exp_model] class [modell] method[get_model] Python script name [exp_model.py] line number [33] error message [[Errno 2] No such file or directory: 'experiment_result.json']]]] 
2022-06-05/10:16:21		Exception occured Failed during training in module [cv_image_suit.Experiment_Layer.model_finder] class [modelfinder] method[find_batchsize] Python script name [model_finder.py] line number [243] error message [list index out of range] 
2022-06-05/10:16:21		Exception occured Failed during training in module [cv_image_suit.Experiment_Layer.model_finder] class [modelfinder] method[write_model_result] Python script name [model_finder.py] line number [152] error message ['NoneType' object has no attribute 'keys'] 
2022-06-05/10:16:22		Exception occured Failed during training in module [cv_image_suit.Experiment_Layer.model_finder] class [modelfinder] method[optimizer_find] Python script name [model_finder.py] line number [208] error message [list index out of range] 
2022-06-05/10:16:22		Exception occured Failed during training in module [cv_image_suit.Experiment_Layer.model_finder] class [modelfinder] method[write_model_result] Python script name [model_finder.py] line number [152] error message ['NoneType' object has no attribute 'keys'] 
2022-06-05/10:21:39		Exception occured Failed during training in module [cv_image_suit.Experiment_Layer.model_finder] class [modelfinder] method[find_batchsize] Python script name [model_finder.py] line number [243] error message [list index out of range] 
2022-06-05/10:21:39		Exception occured Failed during training in module [cv_image_suit.Experiment_Layer.model_finder] class [modelfinder] method[write_model_result] Python script name [model_finder.py] line number [152] error message ['NoneType' object has no attribute 'keys'] 
2022-06-05/10:21:39		Exception occured Failed during training in module [cv_image_suit.Experiment_Layer.model_finder] class [modelfinder] method[optimizer_find] Python script name [model_finder.py] line number [208] error message [list index out of range] 
2022-06-05/10:21:39		Exception occured Failed during training in module [cv_image_suit.Experiment_Layer.model_finder] class [modelfinder] method[write_model_result] Python script name [model_finder.py] line number [152] error message ['NoneType' object has no attribute 'keys'] 
